#VRML_SIM R2022a utf8
WorldInfo {
}
Viewpoint {
  orientation -0.09021189371157748 0.03765407766498649 0.9952105227881035 2.3542067223588976
  position 1.7117286111470202 -1.6015432263279956 0.662485763695901
}
TexturedBackground {
}
TexturedBackgroundLight {
}
RectangleArena {
}
Robot {
  translation 0 0 0.03
  children [
    Shape {
      appearance Appearance {
        material Material {
          diffuseColor 0 0 1
          emissiveColor 0 0 1
          specularColor 0 0 1
        }
      }
      geometry DEF Main_Box Box {
        size 0.3 0.3 0.05
      }
    }
    Transform {
      translation 0 0 0.06
      children [
        SliderJoint {
          jointParameters JointParameters {
            position 8.243330914686764e-05
            maxStop 10
          }
          device [
            LinearMotor {
              acceleration 1
              maxPosition 10
            }
          ]
          endPoint Solid {
            translation 3.7954642454421994e-18 3.266504851151604e-18 -0.0001452468812530583
            rotation -0.9894169551300901 -0.144958825469178 0.006405296222507435 1.2240591808758028e-16
            children [
              Shape {
                geometry DEF Lift Box {
                  size 0.1 0.1 0.1
                }
              }
            ]
            boundingObject USE Lift
            physics Physics {
            }
          }
        }
      ]
      translationStep 0.1
    }
  ]
  name "Robot"
  boundingObject USE Main_Box
  physics Physics {
  }
}
